Workbook

Sheet Synthèse_Population
A1: PRICE TEST — POPULATION CIBLE
A2: Analyse par année × population price test · pondération par exposition
A4: 1 · SYNTHÈSE GLOBALE PAR ANNÉE
A5: Année | B5: Exposition | C5: Ressource HT | D5: Prime TTC moy. pondérée | E5: Maj moy. pondérée | F5: ELR pondéré | G5: Taux résil. hors | H5: Taux résil. fenêtre | I5: Taux résil. total
A6: 2022 | B6: =SUMIF(Base_Population!$A$2:$A$41,A6,Base_Population!$C$2:$C$41) -> 695672 | C6: =SUMIF(Base_Population!$A$2:$A$41,A6,Base_Population!$E$2:$E$41) -> 4.7969937e+08 | D6: =C6/B6 -> 689.54819 | E6: =SUMPRODUCT((Base_Population!$A$2:$A$41=A6)*Base_Population!$C$2:$C$41*Base_Population!$F$2:$F$41)/B6 -> 1.0160489 | F6: =SUMPRODUCT((Base_Population!$A$2:$A$41=A6)*Base_Population!$C$2:$C$41*Base_Population!$G$2:$G$41)/B6 -> 0.78793519 | G6: =SUMPRODUCT((Base_Population!$A$2:$A$41=A6)*Base_Population!$C$2:$C$41*Base_Population!$H$2:$H$41)/B6 -> 16.219892 | H6: =SUMPRODUCT((Base_Population!$A$2:$A$41=A6)*Base_Population!$C$2:$C$41*Base_Population!$I$2:$I$41)/B6 -> 7.5239626 | I6: =G6+H6 -> 23.743854
A7: 2023 | B7: =SUMIF(Base_Population!$A$2:$A$41,A7,Base_Population!$C$2:$C$41) -> 917545 | C7: =SUMIF(Base_Population!$A$2:$A$41,A7,Base_Population!$E$2:$E$41) -> 7.0986085e+08 | D7: =C7/B7 -> 773.65236 | E7: =SUMPRODUCT((Base_Population!$A$2:$A$41=A7)*Base_Population!$C$2:$C$41*Base_Population!$F$2:$F$41)/B7 -> 1.0457529 | F7: =SUMPRODUCT((Base_Population!$A$2:$A$41=A7)*Base_Population!$C$2:$C$41*Base_Population!$G$2:$G$41)/B7 -> 0.71035846 | G7: =SUMPRODUCT((Base_Population!$A$2:$A$41=A7)*Base_Population!$C$2:$C$41*Base_Population!$H$2:$H$41)/B7 -> 7.8717701 | H7: =SUMPRODUCT((Base_Population!$A$2:$A$41=A7)*Base_Population!$C$2:$C$41*Base_Population!$I$2:$I$41)/B7 -> 8.2302655 | I7: =G7+H7 -> 16.102036
A8: 2024 | B8: =SUMIF(Base_Population!$A$2:$A$41,A8,Base_Population!$C$2:$C$41) -> 987049 | C8: =SUMIF(Base_Population!$A$2:$A$41,A8,Base_Population!$E$2:$E$41) -> 801408600 | D8: =C8/B8 -> 811.92383 | E8: =SUMPRODUCT((Base_Population!$A$2:$A$41=A8)*Base_Population!$C$2:$C$41*Base_Population!$F$2:$F$41)/B8 -> 1.058401 | F8: =SUMPRODUCT((Base_Population!$A$2:$A$41=A8)*Base_Population!$C$2:$C$41*Base_Population!$G$2:$G$41)/B8 -> 0.69032689 | G8: =SUMPRODUCT((Base_Population!$A$2:$A$41=A8)*Base_Population!$C$2:$C$41*Base_Population!$H$2:$H$41)/B8 -> 14.348543 | H8: =SUMPRODUCT((Base_Population!$A$2:$A$41=A8)*Base_Population!$C$2:$C$41*Base_Population!$I$2:$I$41)/B8 -> 8.4825213 | I8: =G8+H8 -> 22.831064
A9: 2025 | B9: =SUMIF(Base_Population!$A$2:$A$41,A9,Base_Population!$C$2:$C$41) -> 1054625 | C9: =SUMIF(Base_Population!$A$2:$A$41,A9,Base_Population!$E$2:$E$41) -> 904220970 | D9: =C9/B9 -> 857.38625 | E9: =SUMPRODUCT((Base_Population!$A$2:$A$41=A9)*Base_Population!$C$2:$C$41*Base_Population!$F$2:$F$41)/B9 -> 1.075603 | F9: =SUMPRODUCT((Base_Population!$A$2:$A$41=A9)*Base_Population!$C$2:$C$41*Base_Population!$G$2:$G$41)/B9 -> 0.66780888 | G9: =SUMPRODUCT((Base_Population!$A$2:$A$41=A9)*Base_Population!$C$2:$C$41*Base_Population!$H$2:$H$41)/B9 -> 14.879716 | H9: =SUMPRODUCT((Base_Population!$A$2:$A$41=A9)*Base_Population!$C$2:$C$41*Base_Population!$I$2:$I$41)/B9 -> 8.9071246 | I9: =G9+H9 -> 23.78684
A12: 2 · VOLUMÉTRIE — EXPOSITION PAR MODALITÉ × ANNÉE
A13: Population | B13: 2022 | C13: 2023 | D13: 2024 | E13: 2025 | F13: Total | G13: % Total
A14: Non defini | B14: =SUMIFS(Base_Population!$C$2:$C$41,Base_Population!$A$2:$A$41,2022,Base_Population!$B$2:$B$41,$A14) -> 317399 | C14: =SUMIFS(Base_Population!$C$2:$C$41,Base_Population!$A$2:$A$41,2023,Base_Population!$B$2:$B$41,$A14) -> 438800 | D14: =SUMIFS(Base_Population!$C$2:$C$41,Base_Population!$A$2:$A$41,2024,Base_Population!$B$2:$B$41,$A14) -> 471250 | E14: =SUMIFS(Base_Population!$C$2:$C$41,Base_Population!$A$2:$A$41,2025,Base_Population!$B$2:$B$41,$A14) -> 503800 | F14: =SUM(B14:E14) -> 1731249 | G14: =F14/$F$24 -> 0.47368006
A15: Price Test | B15: =SUMIFS(Base_Population!$C$2:$C$41,Base_Population!$A$2:$A$41,2022,Base_Population!$B$2:$B$41,$A15) -> 5852 | C15: =SUMIFS(Base_Population!$C$2:$C$41,Base_Population!$A$2:$A$41,2023,Base_Population!$B$2:$B$41,$A15) -> 5095 | D15: =SUMIFS(Base_Population!$C$2:$C$41,Base_Population!$A$2:$A$41,2024,Base_Population!$B$2:$B$41,$A15) -> 5238 | E15: =SUMIFS(Base_Population!$C$2:$C$41,Base_Population!$A$2:$A$41,2025,Base_Population!$B$2:$B$41,$A15) -> 5485 | F15: =SUM(B15:E15) -> 21670 | G15: =F15/$F$24 -> 0.0059290414
A16: Price test Sans Ant -2% | B16: =SUMIFS(Base_Population!$C$2:$C$41,Base_Population!$A$2:$A$41,2022,Base_Population!$B$2:$B$41,$A16) -> 11062 | C16: =SUMIFS(Base_Population!$C$2:$C$41,Base_Population!$A$2:$A$41,2023,Base_Population!$B$2:$B$41,$A16) -> 465 | D16: =SUMIFS(Base_Population!$C$2:$C$41,Base_Population!$A$2:$A$41,2024,Base_Population!$B$2:$B$41,$A16) -> 1045 | E16: =SUMIFS(Base_Population!$C$2:$C$41,Base_Population!$A$2:$A$41,2025,Base_Population!$B$2:$B$41,$A16) -> 1180 | F16: =SUM(B16:E16) -> 13752 | G16: =F16/$F$24 -> 0.0037626293
A17: Price test Sans Ant -3% | B17: =SUMIFS(Base_Population!$C$2:$C$41,Base_Population!$A$2:$A$41,2022,Base_Population!$B$2:$B$41,$A17) -> 3489 | C17: =SUMIFS(Base_Population!$C$2:$C$41,Base_Population!$A$2:$A$41,2023,Base_Population!$B$2:$B$41,$A17) -> 887 | D17: =SUMIFS(Base_Population!$C$2:$C$41,Base_Population!$A$2:$A$41,2024,Base_Population!$B$2:$B$41,$A17) -> 968 | E17: =SUMIFS(Base_Population!$C$2:$C$41,Base_Population!$A$2:$A$41,2025,Base_Population!$B$2:$B$41,$A17) -> 1050 | F17: =SUM(B17:E17) -> 6394 | G17: =F17/$F$24 -> 0.0017494366
A18: Price test Sans Ant -4% | B18: =SUMIFS(Base_Population!$C$2:$C$41,Base_Population!$A$2:$A$41,2022,Base_Population!$B$2:$B$41,$A18) -> 406 | C18: =SUMIFS(Base_Population!$C$2:$C$41,Base_Population!$A$2:$A$41,2023,Base_Population!$B$2:$B$41,$A18) -> 520 | D18: =SUMIFS(Base_Population!$C$2:$C$41,Base_Population!$A$2:$A$41,2024,Base_Population!$B$2:$B$41,$A18) -> 720 | E18: =SUMIFS(Base_Population!$C$2:$C$41,Base_Population!$A$2:$A$41,2025,Base_Population!$B$2:$B$41,$A18) -> 815 | F18: =SUM(B18:E18) -> 2461 | G18: =F18/$F$24 -> 0.00067334429
A19: Price test Sans Ant -5% | B19: =SUMIFS(Base_Population!$C$2:$C$41,Base_Population!$A$2:$A$41,2022,Base_Population!$B$2:$B$41,$A19) -> 6513 | C19: =SUMIFS(Base_Population!$C$2:$C$41,Base_Population!$A$2:$A$41,2023,Base_Population!$B$2:$B$41,$A19) -> 640 | D19: =SUMIFS(Base_Population!$C$2:$C$41,Base_Population!$A$2:$A$41,2024,Base_Population!$B$2:$B$41,$A19) -> 858 | E19: =SUMIFS(Base_Population!$C$2:$C$41,Base_Population!$A$2:$A$41,2025,Base_Population!$B$2:$B$41,$A19) -> 930 | F19: =SUM(B19:E19) -> 8941 | G19: =F19/$F$24 -> 0.002446311
A20: Psy test - Baisse : non | B20: =SUMIFS(Base_Population!$C$2:$C$41,Base_Population!$A$2:$A$41,2022,Base_Population!$B$2:$B$41,$A20) -> 647 | C20: =SUMIFS(Base_Population!$C$2:$C$41,Base_Population!$A$2:$A$41,2023,Base_Population!$B$2:$B$41,$A20) -> 371 | D20: =SUMIFS(Base_Population!$C$2:$C$41,Base_Population!$A$2:$A$41,2024,Base_Population!$B$2:$B$41,$A20) -> 420 | E20: =SUMIFS(Base_Population!$C$2:$C$41,Base_Population!$A$2:$A$41,2025,Base_Population!$B$2:$B$41,$A20) -> 480 | F20: =SUM(B20:E20) -> 1918 | G20: =F20/$F$24 -> 0.00052477625
A21: Psy test - Baisse : oui | B21: =SUMIFS(Base_Population!$C$2:$C$41,Base_Population!$A$2:$A$41,2022,Base_Population!$B$2:$B$41,$A21) -> 465 | C21: =SUMIFS(Base_Population!$C$2:$C$41,Base_Population!$A$2:$A$41,2023,Base_Population!$B$2:$B$41,$A21) -> 754 | D21: =SUMIFS(Base_Population!$C$2:$C$41,Base_Population!$A$2:$A$41,2024,Base_Population!$B$2:$B$41,$A21) -> 810 | E21: =SUMIFS(Base_Population!$C$2:$C$41,Base_Population!$A$2:$A$41,2025,Base_Population!$B$2:$B$41,$A21) -> 890 | F21: =SUM(B21:E21) -> 2919 | G21: =F21/$F$24 -> 0.00079865583
A22: Verbatim Gel | B22: =SUMIFS(Base_Population!$C$2:$C$41,Base_Population!$A$2:$A$41,2022,Base_Population!$B$2:$B$41,$A22) -> 343687 | C22: =SUMIFS(Base_Population!$C$2:$C$41,Base_Population!$A$2:$A$41,2023,Base_Population!$B$2:$B$41,$A22) -> 463025 | D22: =SUMIFS(Base_Population!$C$2:$C$41,Base_Population!$A$2:$A$41,2024,Base_Population!$B$2:$B$41,$A22) -> 498320 | E22: =SUMIFS(Base_Population!$C$2:$C$41,Base_Population!$A$2:$A$41,2025,Base_Population!$B$2:$B$41,$A22) -> 532100 | F22: =SUM(B22:E22) -> 1837132 | G22: =F22/$F$24 -> 0.50265028
A23: Verbatim temoin | B23: =SUMIFS(Base_Population!$C$2:$C$41,Base_Population!$A$2:$A$41,2022,Base_Population!$B$2:$B$41,$A23) -> 6152 | C23: =SUMIFS(Base_Population!$C$2:$C$41,Base_Population!$A$2:$A$41,2023,Base_Population!$B$2:$B$41,$A23) -> 6988 | D23: =SUMIFS(Base_Population!$C$2:$C$41,Base_Population!$A$2:$A$41,2024,Base_Population!$B$2:$B$41,$A23) -> 7420 | E23: =SUMIFS(Base_Population!$C$2:$C$41,Base_Population!$A$2:$A$41,2025,Base_Population!$B$2:$B$41,$A23) -> 7895 | F23: =SUM(B23:E23) -> 28455 | G23: =F23/$F$24 -> 0.0077854579
A24: TOTAL | B24: =SUM(B14:B23) -> 695672 | C24: =SUM(C14:C23) -> 917545 | D24: =SUM(D14:D23) -> 987049 | E24: =SUM(E14:E23) -> 1054625 | F24: =SUM(F14:F23) -> 3654891
A27: 3 · RESSOURCE HT PAR MODALITÉ × ANNÉE
A28: Population | B28: 2022 | C28: 2023 | D28: 2024 | E28: 2025 | F28: Total | G28: % Total
A29: Non defini | B29: =SUMIFS(Base_Population!$E$2:$E$41,Base_Population!$A$2:$A$41,2022,Base_Population!$B$2:$B$41,$A29) -> 2.1021046e+08 | C29: =SUMIFS(Base_Population!$E$2:$E$41,Base_Population!$A$2:$A$41,2023,Base_Population!$B$2:$B$41,$A29) -> 3.3028323e+08 | D29: =SUMIFS(Base_Population!$E$2:$E$41,Base_Population!$A$2:$A$41,2024,Base_Population!$B$2:$B$41,$A29) -> 372618500 | E29: =SUMIFS(Base_Population!$E$2:$E$41,Base_Population!$A$2:$A$41,2025,Base_Population!$B$2:$B$41,$A29) -> 425282500 | F29: =SUM(B29:E29) -> 1.3383947e+09 | G29: =F29/$F$39 -> 0.46228219
A30: Price Test | B30: =SUMIFS(Base_Population!$E$2:$E$41,Base_Population!$A$2:$A$41,2022,Base_Population!$B$2:$B$41,$A30) -> 3629802.8 | C30: =SUMIFS(Base_Population!$E$2:$E$41,Base_Population!$A$2:$A$41,2023,Base_Population!$B$2:$B$41,$A30) -> 3433842.8 | D30: =SUMIFS(Base_Population!$E$2:$E$41,Base_Population!$A$2:$A$41,2024,Base_Population!$B$2:$B$41,$A30) -> 3624880 | E30: =SUMIFS(Base_Population!$E$2:$E$41,Base_Population!$A$2:$A$41,2025,Base_Population!$B$2:$B$41,$A30) -> 3928050 | F30: =SUM(B30:E30) -> 14616576 | G30: =F30/$F$39 -> 0.0050485725
A31: Price test Sans Ant -2% | B31: =SUMIFS(Base_Population!$E$2:$E$41,Base_Population!$A$2:$A$41,2022,Base_Population!$B$2:$B$41,$A31) -> 10232318 | C31: =SUMIFS(Base_Population!$E$2:$E$41,Base_Population!$A$2:$A$41,2023,Base_Population!$B$2:$B$41,$A31) -> 330006.17 | D31: =SUMIFS(Base_Population!$E$2:$E$41,Base_Population!$A$2:$A$41,2024,Base_Population!$B$2:$B$41,$A31) -> 769290 | E31: =SUMIFS(Base_Population!$E$2:$E$41,Base_Population!$A$2:$A$41,2025,Base_Population!$B$2:$B$41,$A31) -> 893520 | F31: =SUM(B31:E31) -> 12225134 | G31: =F31/$F$39 -> 0.0042225675
A32: Price test Sans Ant -3% | B32: =SUMIFS(Base_Population!$E$2:$E$41,Base_Population!$A$2:$A$41,2022,Base_Population!$B$2:$B$41,$A32) -> 3090702.7 | C32: =SUMIFS(Base_Population!$E$2:$E$41,Base_Population!$A$2:$A$41,2023,Base_Population!$B$2:$B$41,$A32) -> 595618.94 | D32: =SUMIFS(Base_Population!$E$2:$E$41,Base_Population!$A$2:$A$41,2024,Base_Population!$B$2:$B$41,$A32) -> 701250 | E32: =SUMIFS(Base_Population!$E$2:$E$41,Base_Population!$A$2:$A$41,2025,Base_Population!$B$2:$B$41,$A32) -> 781800 | F32: =SUM(B32:E32) -> 5169371.7 | G32: =F32/$F$39 -> 0.0017855036
A33: Price test Sans Ant -4% | B33: =SUMIFS(Base_Population!$E$2:$E$41,Base_Population!$A$2:$A$41,2022,Base_Population!$B$2:$B$41,$A33) -> 364649.73 | C33: =SUMIFS(Base_Population!$E$2:$E$41,Base_Population!$A$2:$A$41,2023,Base_Population!$B$2:$B$41,$A33) -> 355201 | D33: =SUMIFS(Base_Population!$E$2:$E$41,Base_Population!$A$2:$A$41,2024,Base_Population!$B$2:$B$41,$A33) -> 515780 | E33: =SUMIFS(Base_Population!$E$2:$E$41,Base_Population!$A$2:$A$41,2025,Base_Population!$B$2:$B$41,$A33) -> 597450 | F33: =SUM(B33:E33) -> 1833080.7 | G33: =F33/$F$39 -> 0.000633147
A34: Price test Sans Ant -5% | B34: =SUMIFS(Base_Population!$E$2:$E$41,Base_Population!$A$2:$A$41,2022,Base_Population!$B$2:$B$41,$A34) -> 5324705.1 | C34: =SUMIFS(Base_Population!$E$2:$E$41,Base_Population!$A$2:$A$41,2023,Base_Population!$B$2:$B$41,$A34) -> 428810 | D34: =SUMIFS(Base_Population!$E$2:$E$41,Base_Population!$A$2:$A$41,2024,Base_Population!$B$2:$B$41,$A34) -> 604550 | E34: =SUMIFS(Base_Population!$E$2:$E$41,Base_Population!$A$2:$A$41,2025,Base_Population!$B$2:$B$41,$A34) -> 667890 | F34: =SUM(B34:E34) -> 7025955.1 | G34: =F34/$F$39 -> 0.0024267684
A35: Psy test - Baisse : non | B35: =SUMIFS(Base_Population!$E$2:$E$41,Base_Population!$A$2:$A$41,2022,Base_Population!$B$2:$B$41,$A35) -> 444001.21 | C35: =SUMIFS(Base_Population!$E$2:$E$41,Base_Population!$A$2:$A$41,2023,Base_Population!$B$2:$B$41,$A35) -> 235937.02 | D35: =SUMIFS(Base_Population!$E$2:$E$41,Base_Population!$A$2:$A$41,2024,Base_Population!$B$2:$B$41,$A35) -> 267420 | E35: =SUMIFS(Base_Population!$E$2:$E$41,Base_Population!$A$2:$A$41,2025,Base_Population!$B$2:$B$41,$A35) -> 312780 | F35: =SUM(B35:E35) -> 1260138.2 | G35: =F35/$F$39 -> 0.00043525237
A36: Psy test - Baisse : oui | B36: =SUMIFS(Base_Population!$E$2:$E$41,Base_Population!$A$2:$A$41,2022,Base_Population!$B$2:$B$41,$A36) -> 320143.94 | C36: =SUMIFS(Base_Population!$E$2:$E$41,Base_Population!$A$2:$A$41,2023,Base_Population!$B$2:$B$41,$A36) -> 486715.31 | D36: =SUMIFS(Base_Population!$E$2:$E$41,Base_Population!$A$2:$A$41,2024,Base_Population!$B$2:$B$41,$A36) -> 523880 | E36: =SUMIFS(Base_Population!$E$2:$E$41,Base_Population!$A$2:$A$41,2025,Base_Population!$B$2:$B$41,$A36) -> 588060 | F36: =SUM(B36:E36) -> 1918799.2 | G36: =F36/$F$39 -> 0.00066275422
A37: Verbatim Gel | B37: =SUMIFS(Base_Population!$E$2:$E$41,Base_Population!$A$2:$A$41,2022,Base_Population!$B$2:$B$41,$A37) -> 2.4227386e+08 | C37: =SUMIFS(Base_Population!$E$2:$E$41,Base_Population!$A$2:$A$41,2023,Base_Population!$B$2:$B$41,$A37) -> 3.6924429e+08 | D37: =SUMIFS(Base_Population!$E$2:$E$41,Base_Population!$A$2:$A$41,2024,Base_Population!$B$2:$B$41,$A37) -> 416891250 | E37: =SUMIFS(Base_Population!$E$2:$E$41,Base_Population!$A$2:$A$41,2025,Base_Population!$B$2:$B$41,$A37) -> 465830000 | F37: =SUM(B37:E37) -> 1.4942394e+09 | G37: =F37/$F$39 -> 0.51611103
A38: Verbatim temoin | B38: =SUMIFS(Base_Population!$E$2:$E$41,Base_Population!$A$2:$A$41,2022,Base_Population!$B$2:$B$41,$A38) -> 3808730.4 | C38: =SUMIFS(Base_Population!$E$2:$E$41,Base_Population!$A$2:$A$41,2023,Base_Population!$B$2:$B$41,$A38) -> 4467208.9 | D38: =SUMIFS(Base_Population!$E$2:$E$41,Base_Population!$A$2:$A$41,2024,Base_Population!$B$2:$B$41,$A38) -> 4891800 | E38: =SUMIFS(Base_Population!$E$2:$E$41,Base_Population!$A$2:$A$41,2025,Base_Population!$B$2:$B$41,$A38) -> 5338920 | F38: =SUM(B38:E38) -> 18506659 | G38: =F38/$F$39 -> 0.0063922094
A39: TOTAL | B39: =SUM(B29:B38) -> 4.7969937e+08 | C39: =SUM(C29:C38) -> 7.0986085e+08 | D39: =SUM(D29:D38) -> 801408600 | E39: =SUM(E29:E38) -> 904220970 | F39: =SUM(F29:F38) -> 2.8951898e+09
A42: 4 · MÉTRIQUES QUALITÉ PAR MODALITÉ × ANNÉE
A43: 4a · Coefficient tarifaire moyen (maj_moy)
A44: Population | B44: 2022 | C44: 2023 | D44: 2024 | E44: 2025
A45: Non defini | B45: =IFERROR(SUMIFS(Base_Population!$F$2:$F$41,Base_Population!$A$2:$A$41,2022,Base_Population!$B$2:$B$41,$A45)/SUMIFS(Base_Population!$C$2:$C$41,Base_Population!$A$2:$A$41,2022,Base_Population!$B$2:$B$41,$A45)*SUMIFS(Base_Population!$C$2:$C$41,Base_Population!$A$2:$A$41,2022,Base_Population!$B$2:$B$41,$A45),"") -> 1.0101 | C45: =IFERROR(SUMIFS(Base_Population!$F$2:$F$41,Base_Population!$A$2:$A$41,2023,Base_Population!$B$2:$B$41,$A45)/SUMIFS(Base_Population!$C$2:$C$41,Base_Population!$A$2:$A$41,2023,Base_Population!$B$2:$B$41,$A45)*SUMIFS(Base_Population!$C$2:$C$41,Base_Population!$A$2:$A$41,2023,Base_Population!$B$2:$B$41,$A45),"") -> 1.0521 | D45: =IFERROR(SUMIFS(Base_Population!$F$2:$F$41,Base_Population!$A$2:$A$41,2024,Base_Population!$B$2:$B$41,$A45)/SUMIFS(Base_Population!$C$2:$C$41,Base_Population!$A$2:$A$41,2024,Base_Population!$B$2:$B$41,$A45)*SUMIFS(Base_Population!$C$2:$C$41,Base_Population!$A$2:$A$41,2024,Base_Population!$B$2:$B$41,$A45),"") -> 1.0705 | E45: =IFERROR(SUMIFS(Base_Population!$F$2:$F$41,Base_Population!$A$2:$A$41,2025,Base_Population!$B$2:$B$41,$A45)/SUMIFS(Base_Population!$C$2:$C$41,Base_Population!$A$2:$A$41,2025,Base_Population!$B$2:$B$41,$A45)*SUMIFS(Base_Population!$C$2:$C$41,Base_Population!$A$2:$A$41,2025,Base_Population!$B$2:$B$41,$A45),"") -> 1.0895
A46: Price Test | B46: =IFERROR(SUMIFS(Base_Population!$F$2:$F$41,Base_Population!$A$2:$A$41,2022,Base_Population!$B$2:$B$41,$A46)/SUMIFS(Base_Population!$C$2:$C$41,Base_Population!$A$2:$A$41,2022,Base_Population!$B$2:$B$41,$A46)*SUMIFS(Base_Population!$C$2:$C$41,Base_Population!$A$2:$A$41,2022,Base_Population!$B$2:$B$41,$A46),"") -> 1.0348 | C46: =IFERROR(SUMIFS(Base_Population!$F$2:$F$41,Base_Population!$A$2:$A$41,2023,Base_Population!$B$2:$B$41,$A46)/SUMIFS(Base_Population!$C$2:$C$41,Base_Population!$A$2:$A$41,2023,Base_Population!$B$2:$B$41,$A46)*SUMIFS(Base_Population!$C$2:$C$41,Base_Population!$A$2:$A$41,2023,Base_Population!$B$2:$B$41,$A46),"") -> 1.0737 | D46: =IFERROR(SUMIFS(Base_Population!$F$2:$F$41,Base_Population!$A$2:$A$41,2024,Base_Population!$B$2:$B$41,$A46)/SUMIFS(Base_Population!$C$2:$C$41,Base_Population!$A$2:$A$41,2024,Base_Population!$B$2:$B$41,$A46)*SUMIFS(Base_Population!$C$2:$C$41,Base_Population!$A$2:$A$41,2024,Base_Population!$B$2:$B$41,$A46),"") -> 1.082 | E46: =IFERROR(SUMIFS(Base_Population!$F$2:$F$41,Base_Population!$A$2:$A$41,2025,Base_Population!$B$2:$B$41,$A46)/SUMIFS(Base_Population!$C$2:$C$41,Base_Population!$A$2:$A$41,2025,Base_Population!$B$2:$B$41,$A46)*SUMIFS(Base_Population!$C$2:$C$41,Base_Population!$A$2:$A$41,2025,Base_Population!$B$2:$B$41,$A46),"") -> 1.0985
A47: Price test Sans Ant -2% | B47: =IFERROR(SUMIFS(Base_Population!$F$2:$F$41,Base_Population!$A$2:$A$41,2022,Base_Population!$B$2:$B$41,$A47)/SUMIFS(Base_Population!$C$2:$C$41,Base_Population!$A$2:$A$41,2022,Base_Population!$B$2:$B$41,$A47)*SUMIFS(Base_Population!$C$2:$C$41,Base_Population!$A$2:$A$41,2022,Base_Population!$B$2:$B$41,$A47),"") -> 0.98 | C47: =IFERROR(SUMIFS(Base_Population!$F$2:$F$41,Base_Population!$A$2:$A$41,2023,Base_Population!$B$2:$B$41,$A47)/SUMIFS(Base_Population!$C$2:$C$41,Base_Population!$A$2:$A$41,2023,Base_Population!$B$2:$B$41,$A47)*SUMIFS(Base_Population!$C$2:$C$41,Base_Population!$A$2:$A$41,2023,Base_Population!$B$2:$B$41,$A47),"") -> 1.0851 | D47: =IFERROR(SUMIFS(Base_Population!$F$2:$F$41,Base_Population!$A$2:$A$41,2024,Base_Population!$B$2:$B$41,$A47)/SUMIFS(Base_Population!$C$2:$C$41,Base_Population!$A$2:$A$41,2024,Base_Population!$B$2:$B$41,$A47)*SUMIFS(Base_Population!$C$2:$C$41,Base_Population!$A$2:$A$41,2024,Base_Population!$B$2:$B$41,$A47),"") -> 1.0733 | E47: =IFERROR(SUMIFS(Base_Population!$F$2:$F$41,Base_Population!$A$2:$A$41,2025,Base_Population!$B$2:$B$41,$A47)/SUMIFS(Base_Population!$C$2:$C$41,Base_Population!$A$2:$A$41,2025,Base_Population!$B$2:$B$41,$A47)*SUMIFS(Base_Population!$C$2:$C$41,Base_Population!$A$2:$A$41,2025,Base_Population!$B$2:$B$41,$A47),"") -> 1.0912
...

Sheet Synthèse_Majoration
A1: PRICE TEST — MAJORATION SIMULÉE
A2: Analyse par année × niveau de majoration (-2%, -1%, 0, +1%, +2%)
A4: 1 · SYNTHÈSE GLOBALE PAR ANNÉE
A5: Année | B5: Exposition | C5: Ressource HT | D5: Maj moy. pondérée | E5: ELR pondéré | F5: Nb résil. total | G5: Taux résil. global pondéré | H5: Taux résil. fenêtre pondéré
A6: 2022 | B6: =SUMIF(Base_Majoration!$A$2:$A$21,A6,Base_Majoration!$C$2:$C$21) -> 5852 | C6: =SUMIF(Base_Majoration!$A$2:$A$21,A6,Base_Majoration!$D$2:$D$21) -> 3629802.8 | D6: =SUMPRODUCT((Base_Majoration!$A$2:$A$21=A6)*Base_Majoration!$C$2:$C$21*Base_Majoration!$E$2:$E$21)/B6 -> 1.0347698 | E6: =SUMPRODUCT((Base_Majoration!$A$2:$A$21=A6)*Base_Majoration!$C$2:$C$21*Base_Majoration!$F$2:$F$21)/B6 -> 0.81925198 | F6: =SUMIF(Base_Majoration!$A$2:$A$21,A6,Base_Majoration!$I$2:$I$21) -> 1181 | G6: =SUMPRODUCT((Base_Majoration!$A$2:$A$21=A6)*Base_Majoration!$C$2:$C$21*Base_Majoration!$J$2:$J$21)/B6 -> 20.180022 | H6: =SUMPRODUCT((Base_Majoration!$A$2:$A$21=A6)*Base_Majoration!$C$2:$C$21*Base_Majoration!$K$2:$K$21)/B6 -> 6.5101452
A7: 2023 | B7: =SUMIF(Base_Majoration!$A$2:$A$21,A7,Base_Majoration!$C$2:$C$21) -> 6152 | C7: =SUMIF(Base_Majoration!$A$2:$A$21,A7,Base_Majoration!$D$2:$D$21) -> 3808730.4 | D7: =SUMPRODUCT((Base_Majoration!$A$2:$A$21=A7)*Base_Majoration!$C$2:$C$21*Base_Majoration!$E$2:$E$21)/B7 -> 1.0522785 | E7: =SUMPRODUCT((Base_Majoration!$A$2:$A$21=A7)*Base_Majoration!$C$2:$C$21*Base_Majoration!$F$2:$F$21)/B7 -> 0.78131211 | F7: =SUMIF(Base_Majoration!$A$2:$A$21,A7,Base_Majoration!$I$2:$I$21) -> 575 | G7: =SUMPRODUCT((Base_Majoration!$A$2:$A$21=A7)*Base_Majoration!$C$2:$C$21*Base_Majoration!$J$2:$J$21)/B7 -> 9.3500683 | H7: =SUMPRODUCT((Base_Majoration!$A$2:$A$21=A7)*Base_Majoration!$C$2:$C$21*Base_Majoration!$K$2:$K$21)/B7 -> 6.8925845
A8: 2024 | B8: =SUMIF(Base_Majoration!$A$2:$A$21,A8,Base_Majoration!$C$2:$C$21) -> 5095 | C8: =SUMIF(Base_Majoration!$A$2:$A$21,A8,Base_Majoration!$D$2:$D$21) -> 3433842.8 | D8: =SUMPRODUCT((Base_Majoration!$A$2:$A$21=A8)*Base_Majoration!$C$2:$C$21*Base_Majoration!$E$2:$E$21)/B8 -> 1.0736908 | E8: =SUMPRODUCT((Base_Majoration!$A$2:$A$21=A8)*Base_Majoration!$C$2:$C$21*Base_Majoration!$F$2:$F$21)/B8 -> 0.70519297 | F8: =SUMIF(Base_Majoration!$A$2:$A$21,A8,Base_Majoration!$I$2:$I$21) -> 835 | G8: =SUMPRODUCT((Base_Majoration!$A$2:$A$21=A8)*Base_Majoration!$C$2:$C$21*Base_Majoration!$J$2:$J$21)/B8 -> 16.390179 | H8: =SUMPRODUCT((Base_Majoration!$A$2:$A$21=A8)*Base_Majoration!$C$2:$C$21*Base_Majoration!$K$2:$K$21)/B8 -> 7.1648852
A9: 2025 | B9: =SUMIF(Base_Majoration!$A$2:$A$21,A9,Base_Majoration!$C$2:$C$21) -> 21831 | C9: =SUMIF(Base_Majoration!$A$2:$A$21,A9,Base_Majoration!$D$2:$D$21) -> 16680606 | D9: =SUMPRODUCT((Base_Majoration!$A$2:$A$21=A9)*Base_Majoration!$C$2:$C$21*Base_Majoration!$E$2:$E$21)/B9 -> 1.0697572 | E9: =SUMPRODUCT((Base_Majoration!$A$2:$A$21=A9)*Base_Majoration!$C$2:$C$21*Base_Majoration!$F$2:$F$21)/B9 -> 0.65492317 | F9: =SUMIF(Base_Majoration!$A$2:$A$21,A9,Base_Majoration!$I$2:$I$21) -> 2797 | G9: =SUMPRODUCT((Base_Majoration!$A$2:$A$21=A9)*Base_Majoration!$C$2:$C$21*Base_Majoration!$J$2:$J$21)/B9 -> 12.814372 | H9: =SUMPRODUCT((Base_Majoration!$A$2:$A$21=A9)*Base_Majoration!$C$2:$C$21*Base_Majoration!$K$2:$K$21)/B9 -> 8.1907471
A12: 2 · VOLUMÉTRIE — EXPOSITION PAR NIVEAU × ANNÉE
A13: Niveau | B13: 2022 | C13: 2023 | D13: 2024 | E13: 2025 | F13: Total | G13: % Total
A14: -0.02 | B14: =SUMIFS(Base_Majoration!$C$2:$C$21,Base_Majoration!$A$2:$A$21,2022,Base_Majoration!$B$2:$B$21,$A14) -> 1158 | C14: =SUMIFS(Base_Majoration!$C$2:$C$21,Base_Majoration!$A$2:$A$21,2023,Base_Majoration!$B$2:$B$21,$A14) -> 1232 | D14: =SUMIFS(Base_Majoration!$C$2:$C$21,Base_Majoration!$A$2:$A$21,2024,Base_Majoration!$B$2:$B$21,$A14) -> 958 | E14: =SUMIFS(Base_Majoration!$C$2:$C$21,Base_Majoration!$A$2:$A$21,2025,Base_Majoration!$B$2:$B$21,$A14) -> 4304 | F14: =SUM(B14:E14) -> 7652 | G14: =F14/$F$19 -> 0.19655792
A15: -0.01 | B15: =SUMIFS(Base_Majoration!$C$2:$C$21,Base_Majoration!$A$2:$A$21,2022,Base_Majoration!$B$2:$B$21,$A15) -> 1145 | C15: =SUMIFS(Base_Majoration!$C$2:$C$21,Base_Majoration!$A$2:$A$21,2023,Base_Majoration!$B$2:$B$21,$A15) -> 1229 | D15: =SUMIFS(Base_Majoration!$C$2:$C$21,Base_Majoration!$A$2:$A$21,2024,Base_Majoration!$B$2:$B$21,$A15) -> 1028 | E15: =SUMIFS(Base_Majoration!$C$2:$C$21,Base_Majoration!$A$2:$A$21,2025,Base_Majoration!$B$2:$B$21,$A15) -> 4373 | F15: =SUM(B15:E15) -> 7775 | G15: =F15/$F$19 -> 0.19971744
A16: 0 | B16: =SUMIFS(Base_Majoration!$C$2:$C$21,Base_Majoration!$A$2:$A$21,2022,Base_Majoration!$B$2:$B$21,$A16) -> 1164 | C16: =SUMIFS(Base_Majoration!$C$2:$C$21,Base_Majoration!$A$2:$A$21,2023,Base_Majoration!$B$2:$B$21,$A16) -> 1254 | D16: =SUMIFS(Base_Majoration!$C$2:$C$21,Base_Majoration!$A$2:$A$21,2024,Base_Majoration!$B$2:$B$21,$A16) -> 1045 | E16: =SUMIFS(Base_Majoration!$C$2:$C$21,Base_Majoration!$A$2:$A$21,2025,Base_Majoration!$B$2:$B$21,$A16) -> 4322 | F16: =SUM(B16:E16) -> 7785 | G16: =F16/$F$19 -> 0.19997431
A17: 0.01 | B17: =SUMIFS(Base_Majoration!$C$2:$C$21,Base_Majoration!$A$2:$A$21,2022,Base_Majoration!$B$2:$B$21,$A17) -> 1183 | C17: =SUMIFS(Base_Majoration!$C$2:$C$21,Base_Majoration!$A$2:$A$21,2023,Base_Majoration!$B$2:$B$21,$A17) -> 1224 | D17: =SUMIFS(Base_Majoration!$C$2:$C$21,Base_Majoration!$A$2:$A$21,2024,Base_Majoration!$B$2:$B$21,$A17) -> 986 | E17: =SUMIFS(Base_Majoration!$C$2:$C$21,Base_Majoration!$A$2:$A$21,2025,Base_Majoration!$B$2:$B$21,$A17) -> 4382 | F17: =SUM(B17:E17) -> 7775 | G17: =F17/$F$19 -> 0.19971744
A18: 0.02 | B18: =SUMIFS(Base_Majoration!$C$2:$C$21,Base_Majoration!$A$2:$A$21,2022,Base_Majoration!$B$2:$B$21,$A18) -> 1202 | C18: =SUMIFS(Base_Majoration!$C$2:$C$21,Base_Majoration!$A$2:$A$21,2023,Base_Majoration!$B$2:$B$21,$A18) -> 1213 | D18: =SUMIFS(Base_Majoration!$C$2:$C$21,Base_Majoration!$A$2:$A$21,2024,Base_Majoration!$B$2:$B$21,$A18) -> 1078 | E18: =SUMIFS(Base_Majoration!$C$2:$C$21,Base_Majoration!$A$2:$A$21,2025,Base_Majoration!$B$2:$B$21,$A18) -> 4450 | F18: =SUM(B18:E18) -> 7943 | G18: =F18/$F$19 -> 0.20403288
A19: TOTAL | B19: =SUM(B14:B18) -> 5852 | C19: =SUM(C14:C18) -> 6152 | D19: =SUM(D14:D18) -> 5095 | E19: =SUM(E14:E18) -> 21831 | F19: =SUM(F14:F18) -> 38930
A22: 3 · RESSOURCE HT PAR NIVEAU × ANNÉE
A23: Niveau | B23: 2022 | C23: 2023 | D23: 2024 | E23: 2025 | F23: Total | G23: % Total
A24: -0.02 | B24: =SUMIFS(Base_Majoration!$D$2:$D$21,Base_Majoration!$A$2:$A$21,2022,Base_Majoration!$B$2:$B$21,$A24) -> 711310.94 | C24: =SUMIFS(Base_Majoration!$D$2:$D$21,Base_Majoration!$A$2:$A$21,2023,Base_Majoration!$B$2:$B$21,$A24) -> 752901.16 | D24: =SUMIFS(Base_Majoration!$D$2:$D$21,Base_Majoration!$A$2:$A$21,2024,Base_Majoration!$B$2:$B$21,$A24) -> 641495.13 | E24: =SUMIFS(Base_Majoration!$D$2:$D$21,Base_Majoration!$A$2:$A$21,2025,Base_Majoration!$B$2:$B$21,$A24) -> 3201885.8 | F24: =SUM(B24:E24) -> 5307593.1 | G24: =F24/$F$29 -> 0.19263226
A25: -0.01 | B25: =SUMIFS(Base_Majoration!$D$2:$D$21,Base_Majoration!$A$2:$A$21,2022,Base_Majoration!$B$2:$B$21,$A25) -> 689554.7 | C25: =SUMIFS(Base_Majoration!$D$2:$D$21,Base_Majoration!$A$2:$A$21,2023,Base_Majoration!$B$2:$B$21,$A25) -> 750670.04 | D25: =SUMIFS(Base_Majoration!$D$2:$D$21,Base_Majoration!$A$2:$A$21,2024,Base_Majoration!$B$2:$B$21,$A25) -> 678667.36 | E25: =SUMIFS(Base_Majoration!$D$2:$D$21,Base_Majoration!$A$2:$A$21,2025,Base_Majoration!$B$2:$B$21,$A25) -> 3298961.6 | F25: =SUM(B25:E25) -> 5417853.7 | G25: =F25/$F$29 -> 0.19663402
A26: 0 | B26: =SUMIFS(Base_Majoration!$D$2:$D$21,Base_Majoration!$A$2:$A$21,2022,Base_Majoration!$B$2:$B$21,$A26) -> 725753.17 | C26: =SUMIFS(Base_Majoration!$D$2:$D$21,Base_Majoration!$A$2:$A$21,2023,Base_Majoration!$B$2:$B$21,$A26) -> 766789.35 | D26: =SUMIFS(Base_Majoration!$D$2:$D$21,Base_Majoration!$A$2:$A$21,2024,Base_Majoration!$B$2:$B$21,$A26) -> 703196.34 | E26: =SUMIFS(Base_Majoration!$D$2:$D$21,Base_Majoration!$A$2:$A$21,2025,Base_Majoration!$B$2:$B$21,$A26) -> 3308102 | F26: =SUM(B26:E26) -> 5503840.8 | G26: =F26/$F$29 -> 0.19975482
A27: 0.01 | B27: =SUMIFS(Base_Majoration!$D$2:$D$21,Base_Majoration!$A$2:$A$21,2022,Base_Majoration!$B$2:$B$21,$A27) -> 743643.87 | C27: =SUMIFS(Base_Majoration!$D$2:$D$21,Base_Majoration!$A$2:$A$21,2023,Base_Majoration!$B$2:$B$21,$A27) -> 762878.78 | D27: =SUMIFS(Base_Majoration!$D$2:$D$21,Base_Majoration!$A$2:$A$21,2024,Base_Majoration!$B$2:$B$21,$A27) -> 665600.99 | E27: =SUMIFS(Base_Majoration!$D$2:$D$21,Base_Majoration!$A$2:$A$21,2025,Base_Majoration!$B$2:$B$21,$A27) -> 3391536.3 | F27: =SUM(B27:E27) -> 5563659.9 | G27: =F27/$F$29 -> 0.20192587
A28: 0.02 | B28: =SUMIFS(Base_Majoration!$D$2:$D$21,Base_Majoration!$A$2:$A$21,2022,Base_Majoration!$B$2:$B$21,$A28) -> 759540.16 | C28: =SUMIFS(Base_Majoration!$D$2:$D$21,Base_Majoration!$A$2:$A$21,2023,Base_Majoration!$B$2:$B$21,$A28) -> 775491.11 | D28: =SUMIFS(Base_Majoration!$D$2:$D$21,Base_Majoration!$A$2:$A$21,2024,Base_Majoration!$B$2:$B$21,$A28) -> 744882.99 | E28: =SUMIFS(Base_Majoration!$D$2:$D$21,Base_Majoration!$A$2:$A$21,2025,Base_Majoration!$B$2:$B$21,$A28) -> 3480120 | F28: =SUM(B28:E28) -> 5760034.3 | G28: =F28/$F$29 -> 0.20905303
A29: TOTAL | B29: =SUM(B24:B28) -> 3629802.8 | C29: =SUM(C24:C28) -> 3808730.4 | D29: =SUM(D24:D28) -> 3433842.8 | E29: =SUM(E24:E28) -> 16680606 | F29: =SUM(F24:F28) -> 27552982
A32: 4 · MÉTRIQUES QUALITÉ PAR NIVEAU × ANNÉE
A33: 4a · Coefficient tarifaire moyen (maj_moy)
A34: Niveau | B34: 2022 | C34: 2023 | D34: 2024 | E34: 2025
A35: -0.02 | B35: =IFERROR(SUMIFS(Base_Majoration!$E$2:$E$21,Base_Majoration!$A$2:$A$21,2022,Base_Majoration!$B$2:$B$21,$A35),"") -> 1.0151 | C35: =IFERROR(SUMIFS(Base_Majoration!$E$2:$E$21,Base_Majoration!$A$2:$A$21,2023,Base_Majoration!$B$2:$B$21,$A35),"") -> 1.0332 | D35: =IFERROR(SUMIFS(Base_Majoration!$E$2:$E$21,Base_Majoration!$A$2:$A$21,2024,Base_Majoration!$B$2:$B$21,$A35),"") -> 1.0541 | E35: =IFERROR(SUMIFS(Base_Majoration!$E$2:$E$21,Base_Majoration!$A$2:$A$21,2025,Base_Majoration!$B$2:$B$21,$A35),"") -> 1.0498
A36: -0.01 | B36: =IFERROR(SUMIFS(Base_Majoration!$E$2:$E$21,Base_Majoration!$A$2:$A$21,2022,Base_Majoration!$B$2:$B$21,$A36),"") -> 1.0247 | C36: =IFERROR(SUMIFS(Base_Majoration!$E$2:$E$21,Base_Majoration!$A$2:$A$21,2023,Base_Majoration!$B$2:$B$21,$A36),"") -> 1.0439 | D36: =IFERROR(SUMIFS(Base_Majoration!$E$2:$E$21,Base_Majoration!$A$2:$A$21,2024,Base_Majoration!$B$2:$B$21,$A36),"") -> 1.0635 | E36: =IFERROR(SUMIFS(Base_Majoration!$E$2:$E$21,Base_Majoration!$A$2:$A$21,2025,Base_Majoration!$B$2:$B$21,$A36),"") -> 1.0595
A37: 0 | B37: =IFERROR(SUMIFS(Base_Majoration!$E$2:$E$21,Base_Majoration!$A$2:$A$21,2022,Base_Majoration!$B$2:$B$21,$A37),"") -> 1.0348 | C37: =IFERROR(SUMIFS(Base_Majoration!$E$2:$E$21,Base_Majoration!$A$2:$A$21,2023,Base_Majoration!$B$2:$B$21,$A37),"") -> 1.0529 | D37: =IFERROR(SUMIFS(Base_Majoration!$E$2:$E$21,Base_Majoration!$A$2:$A$21,2024,Base_Majoration!$B$2:$B$21,$A37),"") -> 1.0733 | E37: =IFERROR(SUMIFS(Base_Majoration!$E$2:$E$21,Base_Majoration!$A$2:$A$21,2025,Base_Majoration!$B$2:$B$21,$A37),"") -> 1.0695
A38: 0.01 | B38: =IFERROR(SUMIFS(Base_Majoration!$E$2:$E$21,Base_Majoration!$A$2:$A$21,2022,Base_Majoration!$B$2:$B$21,$A38),"") -> 1.0441 | C38: =IFERROR(SUMIFS(Base_Majoration!$E$2:$E$21,Base_Majoration!$A$2:$A$21,2023,Base_Majoration!$B$2:$B$21,$A38),"") -> 1.0612 | D38: =IFERROR(SUMIFS(Base_Majoration!$E$2:$E$21,Base_Majoration!$A$2:$A$21,2024,Base_Majoration!$B$2:$B$21,$A38),"") -> 1.0832 | E38: =IFERROR(SUMIFS(Base_Majoration!$E$2:$E$21,Base_Majoration!$A$2:$A$21,2025,Base_Majoration!$B$2:$B$21,$A38),"") -> 1.0798
A39: 0.02 | B39: =IFERROR(SUMIFS(Base_Majoration!$E$2:$E$21,Base_Majoration!$A$2:$A$21,2022,Base_Majoration!$B$2:$B$21,$A39),"") -> 1.0541 | C39: =IFERROR(SUMIFS(Base_Majoration!$E$2:$E$21,Base_Majoration!$A$2:$A$21,2023,Base_Majoration!$B$2:$B$21,$A39),"") -> 1.0705 | D39: =IFERROR(SUMIFS(Base_Majoration!$E$2:$E$21,Base_Majoration!$A$2:$A$21,2024,Base_Majoration!$B$2:$B$21,$A39),"") -> 1.0925 | E39: =IFERROR(SUMIFS(Base_Majoration!$E$2:$E$21,Base_Majoration!$A$2:$A$21,2025,Base_Majoration!$B$2:$B$21,$A39),"") -> 1.0895
A41: 4b · ELR moyen
A42: Niveau | B42: 2022 | C42: 2023 | D42: 2024 | E42: 2025
A43: -0.02 | B43: =IFERROR(SUMIFS(Base_Majoration!$F$2:$F$21,Base_Majoration!$A$2:$A$21,2022,Base_Majoration!$B$2:$B$21,$A43),"") -> 0.8302 | C43: =IFERROR(SUMIFS(Base_Majoration!$F$2:$F$21,Base_Majoration!$A$2:$A$21,2023,Base_Majoration!$B$2:$B$21,$A43),"") -> 0.7859 | D43: =IFERROR(SUMIFS(Base_Majoration!$F$2:$F$21,Base_Majoration!$A$2:$A$21,2024,Base_Majoration!$B$2:$B$21,$A43),"") -> 0.711 | E43: =IFERROR(SUMIFS(Base_Majoration!$F$2:$F$21,Base_Majoration!$A$2:$A$21,2025,Base_Majoration!$B$2:$B$21,$A43),"") -> 0.6604
A44: -0.01 | B44: =IFERROR(SUMIFS(Base_Majoration!$F$2:$F$21,Base_Majoration!$A$2:$A$21,2022,Base_Majoration!$B$2:$B$21,$A44),"") -> 0.8179 | C44: =IFERROR(SUMIFS(Base_Majoration!$F$2:$F$21,Base_Majoration!$A$2:$A$21,2023,Base_Majoration!$B$2:$B$21,$A44),"") -> 0.7855 | D44: =IFERROR(SUMIFS(Base_Majoration!$F$2:$F$21,Base_Majoration!$A$2:$A$21,2024,Base_Majoration!$B$2:$B$21,$A44),"") -> 0.7089 | E44: =IFERROR(SUMIFS(Base_Majoration!$F$2:$F$21,Base_Majoration!$A$2:$A$21,2025,Base_Majoration!$B$2:$B$21,$A44),"") -> 0.6516
A45: 0 | B45: =IFERROR(SUMIFS(Base_Majoration!$F$2:$F$21,Base_Majoration!$A$2:$A$21,2022,Base_Majoration!$B$2:$B$21,$A45),"") -> 0.8261 | C45: =IFERROR(SUMIFS(Base_Majoration!$F$2:$F$21,Base_Majoration!$A$2:$A$21,2023,Base_Majoration!$B$2:$B$21,$A45),"") -> 0.7837 | D45: =IFERROR(SUMIFS(Base_Majoration!$F$2:$F$21,Base_Majoration!$A$2:$A$21,2024,Base_Majoration!$B$2:$B$21,$A45),"") -> 0.7052 | E45: =IFERROR(SUMIFS(Base_Majoration!$F$2:$F$21,Base_Majoration!$A$2:$A$21,2025,Base_Majoration!$B$2:$B$21,$A45),"") -> 0.6534
A46: 0.01 | B46: =IFERROR(SUMIFS(Base_Majoration!$F$2:$F$21,Base_Majoration!$A$2:$A$21,2022,Base_Majoration!$B$2:$B$21,$A46),"") -> 0.8121 | C46: =IFERROR(SUMIFS(Base_Majoration!$F$2:$F$21,Base_Majoration!$A$2:$A$21,2023,Base_Majoration!$B$2:$B$21,$A46),"") -> 0.7761 | D46: =IFERROR(SUMIFS(Base_Majoration!$F$2:$F$21,Base_Majoration!$A$2:$A$21,2024,Base_Majoration!$B$2:$B$21,$A46),"") -> 0.7007 | E46: =IFERROR(SUMIFS(Base_Majoration!$F$2:$F$21,Base_Majoration!$A$2:$A$21,2025,Base_Majoration!$B$2:$B$21,$A46),"") -> 0.6553
A47: 0.02 | B47: =IFERROR(SUMIFS(Base_Majoration!$F$2:$F$21,Base_Majoration!$A$2:$A$21,2022,Base_Majoration!$B$2:$B$21,$A47),"") -> 0.8104 | C47: =IFERROR(SUMIFS(Base_Majoration!$F$2:$F$21,Base_Majoration!$A$2:$A$21,2023,Base_Majoration!$B$2:$B$21,$A47),"") -> 0.7752 | D47: =IFERROR(SUMIFS(Base_Majoration!$F$2:$F$21,Base_Majoration!$A$2:$A$21,2024,Base_Majoration!$B$2:$B$21,$A47),"") -> 0.7006 | E47: =IFERROR(SUMIFS(Base_Majoration!$F$2:$F$21,Base_Majoration!$A$2:$A$21,2025,Base_Majoration!$B$2:$B$21,$A47),"") -> 0.654
A49: 4c · Taux résiliation global
...

Sheet Base_Population
A1: annee | B1: POL_PopulationCiblePriceTest_r | C1: exposition | D1: prime_ttc_moy | E1: ressource_ht | F1: maj_moy | G1: elr_moyen | H1: taux_resil_hors_pct | I1: taux_resil_fenetre_pct
A2: 2022 | B2: Non defini | C2: 317399 | D2: 811.35 | E2: 2.1021046e+08 | F2: 1.0101 | G2: 0.8019 | H2: 16.08 | I2: 7.45
A3: 2022 | B3: Price Test | C3: 5852 | D3: 756.37 | E3: 3629802.8 | F3: 1.0348 | G3: 0.8195 | H3: 13.67 | I3: 6.51
A4: 2022 | B4: Price test Sans Ant -2% | C4: 11062 | D4: 1156.22 | E4: 10232318 | F4: 0.98 | G4: 0.7328 | H4: 18.36 | I4: 9.44
A5: 2022 | B5: Price test Sans Ant -3% | C5: 3489 | D5: 1106.88 | E5: 3090702.7 | F5: 0.97 | G5: 0.7278 | H5: 25.16 | I5: 10.26
A6: 2022 | B6: Price test Sans Ant -4% | C6: 406 | D6: 1119.9 | E6: 364649.73 | F6: 0.96 | G6: 0.738 | H6: 21.67 | I6: 9.11
A7: 2022 | B7: Price test Sans Ant -5% | C7: 6513 | D7: 1018.4 | E7: 5324705.1 | F7: 0.93 | G7: 0.5726 | H7: 19.79 | I7: 9.06
A8: 2022 | B8: Psy test - Baisse : non | C8: 647 | D8: 839.55 | E8: 444001.21 | F8: 1.0079 | G8: 0.7838 | H8: 21.29 | I8: 8.17
A9: 2022 | B9: Psy test - Baisse : oui | C9: 465 | D9: 843.33 | E9: 320143.94 | F9: 1.0268 | G9: 0.7567 | H9: 21.29 | I9: 6.96
A10: 2022 | B10: Verbatim Gel | C10: 343687 | D10: 863.44 | E10: 2.4227386e+08 | F10: 1.0239 | G10: 0.7812 | H10: 16.2 | I10: 7.5
A11: 2022 | B11: Verbatim temoin | C11: 6152 | D11: 754.42 | E11: 3808730.4 | F11: 1.0523 | G11: 0.781 | H11: 13 | I11: 6.89
A12: 2023 | B12: Non defini | C12: 438800 | D12: 918.96 | E12: 3.3028323e+08 | F12: 1.0521 | G12: 0.7231 | H12: 10.02 | I12: 8.37
A13: 2023 | B13: Price Test | C13: 5095 | D13: 820.29 | E13: 3433842.8 | F13: 1.0737 | G13: 0.7052 | H13: 18.09 | I13: 7.16
... A41: 2025 | B41: Verbatim temoin | C41: 7895 | D41: 845.8 | E41: 5338920 | F41: 1.085 | G41: 0.685 | H41: 13.85 | I41: 7.95

Sheet Base_Majoration
A1: annee | B1: POL_MajorationPriceTest_sim | C1: exposition | D1: ressource_ht | E1: maj_moy | F1: elr_moyen | G1: nb_resil_fenetre | H1: nb_resil_hors | I1: nb_resil_total | J1: taux_resil_global | K1: taux_resil_fenetre_pct
A2: 2022 | B2: -0.02 | C2: 1158 | D2: 711310.94 | E2: 1.0151 | F2: 0.8302 | G2: 63 | H2: 146 | I2: 209 | J2: 18.05 | K2: 5.44
A3: 2022 | B3: -0.01 | C3: 1145 | D3: 689554.7 | E3: 1.0247 | F3: 0.8179 | G3: 71 | H3: 160 | I3: 231 | J3: 20.17 | K3: 6.2
A4: 2022 | B4: 0 | C4: 1164 | D4: 725753.17 | E4: 1.0348 | F4: 0.8261 | G4: 73 | H4: 173 | I4: 246 | J4: 21.13 | K4: 6.27
A5: 2022 | B5: 0.01 | C5: 1183 | D5: 743643.87 | E5: 1.0441 | F5: 0.8121 | G5: 85 | H5: 145 | I5: 230 | J5: 19.44 | K5: 7.19
A6: 2022 | B6: 0.02 | C6: 1202 | D6: 759540.16 | E6: 1.0541 | F6: 0.8104 | G6: 89 | H6: 176 | I6: 265 | J6: 22.05 | K6: 7.4
A7: 2023 | B7: -0.02 | C7: 1232 | D7: 752901.16 | E7: 1.0332 | F7: 0.7859 | G7: 82 | H7: 35 | I7: 117 | J7: 9.5 | K7: 6.66
A8: 2023 | B8: -0.01 | C8: 1229 | D8: 750670.04 | E8: 1.0439 | F8: 0.7855 | G8: 87 | H8: 34 | I8: 121 | J8: 9.85 | K8: 7.08
A9: 2023 | B9: 0 | C9: 1254 | D9: 766789.35 | E9: 1.0529 | F9: 0.7837 | G9: 98 | H9: 37 | I9: 135 | J9: 10.77 | K9: 7.81
A10: 2023 | B10: 0.01 | C10: 1224 | D10: 762878.78 | E10: 1.0612 | F10: 0.7761 | G10: 75 | H10: 17 | I10: 92 | J10: 7.52 | K10: 6.13
A11: 2023 | B11: 0.02 | C11: 1213 | D11: 775491.11 | E11: 1.0705 | F11: 0.7752 | G11: 82 | H11: 28 | I11: 110 | J11: 9.07 | K11: 6.76
A12: 2024 | B12: -0.02 | C12: 958 | D12: 641495.13 | E12: 1.0541 | F12: 0.711 | G12: 77 | H12: 95 | I12: 172 | J12: 17.95 | K12: 8.04
A13: 2024 | B13: -0.01 | C13: 1028 | D13: 678667.36 | E13: 1.0635 | F13: 0.7089 | G13: 65 | H13: 90 | I13: 155 | J13: 15.08 | K13: 6.32
... A21: 2025 | B21: 0.02 | C21: 4450 | D21: 3480120 | E21: 1.0895 | F21: 0.654 | G21: 395 | H21: 210 | I21: 605 | J21: 13.6 | K21: 8.88

Sheet Visuels
A1: VISUELS — ANALYSE PAR ANNÉE
A2: Évolution 2022-2025 des métriques price test, vue population et vue majoration
A4: A · Synthèse Population par année (lien dynamique)
A5: Année | B5: Exposition | C5: Ressource HT (M€) | D5: ELR | E5: Résil. total (%)
A6: 2022 | B6: =Synthèse_Population!B6 -> 695672 | C6: =Synthèse_Population!C6/1000000 -> 479.69937 | D6: =Synthèse_Population!F6 -> 0.78793519 | E6: =Synthèse_Population!I6 -> 23.743854
A7: 2023 | B7: =Synthèse_Population!B7 -> 917545 | C7: =Synthèse_Population!C7/1000000 -> 709.86085 | D7: =Synthèse_Population!F7 -> 0.71035846 | E7: =Synthèse_Population!I7 -> 16.102036
A8: 2024 | B8: =Synthèse_Population!B8 -> 987049 | C8: =Synthèse_Population!C8/1000000 -> 801.4086 | D8: =Synthèse_Population!F8 -> 0.69032689 | E8: =Synthèse_Population!I8 -> 22.831064
A9: 2025 | B9: =Synthèse_Population!B9 -> 1054625 | C9: =Synthèse_Population!C9/1000000 -> 904.22097 | D9: =Synthèse_Population!F9 -> 0.66780888 | E9: =Synthèse_Population!I9 -> 23.78684
A12: B · Majoration moyenne par niveau × année
A13: Année | B13: -0.02 | C13: -0.01 | D13: 0 | E13: 0.01 | F13: 0.02
A14: 2022 | B14: =IFERROR(SUMIFS(Base_Majoration!$E$2:$E$21,Base_Majoration!$A$2:$A$21,$A14,Base_Majoration!$B$2:$B$21,B$13),"") -> 1.0151 | C14: =IFERROR(SUMIFS(Base_Majoration!$E$2:$E$21,Base_Majoration!$A$2:$A$21,$A14,Base_Majoration!$B$2:$B$21,B$13),"") -> 1.0151 | D14: =IFERROR(SUMIFS(Base_Majoration!$E$2:$E$21,Base_Majoration!$A$2:$A$21,$A14,Base_Majoration!$B$2:$B$21,B$13),"") -> 1.0151 | E14: =IFERROR(SUMIFS(Base_Majoration!$E$2:$E$21,Base_Majoration!$A$2:$A$21,$A14,Base_Majoration!$B$2:$B$21,B$13),"") -> 1.0151 | F14: =IFERROR(SUMIFS(Base_Majoration!$E$2:$E$21,Base_Majoration!$A$2:$A$21,$A14,Base_Majoration!$B$2:$B$21,B$13),"") -> 1.0151
A15: 2023 | B15: =IFERROR(SUMIFS(Base_Majoration!$E$2:$E$21,Base_Majoration!$A$2:$A$21,$A15,Base_Majoration!$B$2:$B$21,B$13),"") -> 1.0332 | C15: =IFERROR(SUMIFS(Base_Majoration!$E$2:$E$21,Base_Majoration!$A$2:$A$21,$A15,Base_Majoration!$B$2:$B$21,B$13),"") -> 1.0332 | D15: =IFERROR(SUMIFS(Base_Majoration!$E$2:$E$21,Base_Majoration!$A$2:$A$21,$A15,Base_Majoration!$B$2:$B$21,B$13),"") -> 1.0332 | E15: =IFERROR(SUMIFS(Base_Majoration!$E$2:$E$21,Base_Majoration!$A$2:$A$21,$A15,Base_Majoration!$B$2:$B$21,B$13),"") -> 1.0332 | F15: =IFERROR(SUMIFS(Base_Majoration!$E$2:$E$21,Base_Majoration!$A$2:$A$21,$A15,Base_Majoration!$B$2:$B$21,B$13),"") -> 1.0332
A16: 2024 | B16: =IFERROR(SUMIFS(Base_Majoration!$E$2:$E$21,Base_Majoration!$A$2:$A$21,$A16,Base_Majoration!$B$2:$B$21,B$13),"") -> 1.0541 | C16: =IFERROR(SUMIFS(Base_Majoration!$E$2:$E$21,Base_Majoration!$A$2:$A$21,$A16,Base_Majoration!$B$2:$B$21,B$13),"") -> 1.0541 | D16: =IFERROR(SUMIFS(Base_Majoration!$E$2:$E$21,Base_Majoration!$A$2:$A$21,$A16,Base_Majoration!$B$2:$B$21,B$13),"") -> 1.0541 | E16: =IFERROR(SUMIFS(Base_Majoration!$E$2:$E$21,Base_Majoration!$A$2:$A$21,$A16,Base_Majoration!$B$2:$B$21,B$13),"") -> 1.0541 | F16: =IFERROR(SUMIFS(Base_Majoration!$E$2:$E$21,Base_Majoration!$A$2:$A$21,$A16,Base_Majoration!$B$2:$B$21,B$13),"") -> 1.0541
A17: 2025 | B17: =IFERROR(SUMIFS(Base_Majoration!$E$2:$E$21,Base_Majoration!$A$2:$A$21,$A17,Base_Majoration!$B$2:$B$21,B$13),"") -> 1.0498 | C17: =IFERROR(SUMIFS(Base_Majoration!$E$2:$E$21,Base_Majoration!$A$2:$A$21,$A17,Base_Majoration!$B$2:$B$21,B$13),"") -> 1.0498 | D17: =IFERROR(SUMIFS(Base_Majoration!$E$2:$E$21,Base_Majoration!$A$2:$A$21,$A17,Base_Majoration!$B$2:$B$21,B$13),"") -> 1.0498 | E17: =IFERROR(SUMIFS(Base_Majoration!$E$2:$E$21,Base_Majoration!$A$2:$A$21,$A17,Base_Majoration!$B$2:$B$21,B$13),"") -> 1.0498 | F17: =IFERROR(SUMIFS(Base_Majoration!$E$2:$E$21,Base_Majoration!$A$2:$A$21,$A17,Base_Majoration!$B$2:$B$21,B$13),"") -> 1.0498
A38: C · Taux de résiliation global par niveau × année
A39: Année | B39: -0.02 | C39: -0.01 | D39: 0 | E39: 0.01 | F39: 0.02
A40: 2022 | B40: =IFERROR(SUMIFS(Base_Majoration!$J$2:$J$21,Base_Majoration!$A$2:$A$21,$A40,Base_Majoration!$B$2:$B$21,B$39),"") -> 18.05 | C40: =IFERROR(SUMIFS(Base_Majoration!$J$2:$J$21,Base_Majoration!$A$2:$A$21,$A40,Base_Majoration!$B$2:$B$21,B$39),"") -> 18.05 | D40: =IFERROR(SUMIFS(Base_Majoration!$J$2:$J$21,Base_Majoration!$A$2:$A$21,$A40,Base_Majoration!$B$2:$B$21,B$39),"") -> 18.05 | E40: =IFERROR(SUMIFS(Base_Majoration!$J$2:$J$21,Base_Majoration!$A$2:$A$21,$A40,Base_Majoration!$B$2:$B$21,B$39),"") -> 18.05 | F40: =IFERROR(SUMIFS(Base_Majoration!$J$2:$J$21,Base_Majoration!$A$2:$A$21,$A40,Base_Majoration!$B$2:$B$21,B$39),"") -> 18.05
A41: 2023 | B41: =IFERROR(SUMIFS(Base_Majoration!$J$2:$J$21,Base_Majoration!$A$2:$A$21,$A41,Base_Majoration!$B$2:$B$21,B$39),"") -> 9.5 | C41: =IFERROR(SUMIFS(Base_Majoration!$J$2:$J$21,Base_Majoration!$A$2:$A$21,$A41,Base_Majoration!$B$2:$B$21,B$39),"") -> 9.5 | D41: =IFERROR(SUMIFS(Base_Majoration!$J$2:$J$21,Base_Majoration!$A$2:$A$21,$A41,Base_Majoration!$B$2:$B$21,B$39),"") -> 9.5 | E41: =IFERROR(SUMIFS(Base_Majoration!$J$2:$J$21,Base_Majoration!$A$2:$A$21,$A41,Base_Majoration!$B$2:$B$21,B$39),"") -> 9.5 | F41: =IFERROR(SUMIFS(Base_Majoration!$J$2:$J$21,Base_Majoration!$A$2:$A$21,$A41,Base_Majoration!$B$2:$B$21,B$39),"") -> 9.5
A42: 2024 | B42: =IFERROR(SUMIFS(Base_Majoration!$J$2:$J$21,Base_Majoration!$A$2:$A$21,$A42,Base_Majoration!$B$2:$B$21,B$39),"") -> 17.95 | C42: =IFERROR(SUMIFS(Base_Majoration!$J$2:$J$21,Base_Majoration!$A$2:$A$21,$A42,Base_Majoration!$B$2:$B$21,B$39),"") -> 17.95 | D42: =IFERROR(SUMIFS(Base_Majoration!$J$2:$J$21,Base_Majoration!$A$2:$A$21,$A42,Base_Majoration!$B$2:$B$21,B$39),"") -> 17.95 | E42: =IFERROR(SUMIFS(Base_Majoration!$J$2:$J$21,Base_Majoration!$A$2:$A$21,$A42,Base_Majoration!$B$2:$B$21,B$39),"") -> 17.95 | F42: =IFERROR(SUMIFS(Base_Majoration!$J$2:$J$21,Base_Majoration!$A$2:$A$21,$A42,Base_Majoration!$B$2:$B$21,B$39),"") -> 17.95
A43: 2025 | B43: =IFERROR(SUMIFS(Base_Majoration!$J$2:$J$21,Base_Majoration!$A$2:$A$21,$A43,Base_Majoration!$B$2:$B$21,B$39),"") -> 11.78 | C43: =IFERROR(SUMIFS(Base_Majoration!$J$2:$J$21,Base_Majoration!$A$2:$A$21,$A43,Base_Majoration!$B$2:$B$21,B$39),"") -> 11.78 | D43: =IFERROR(SUMIFS(Base_Majoration!$J$2:$J$21,Base_Majoration!$A$2:$A$21,$A43,Base_Majoration!$B$2:$B$21,B$39),"") -> 11.78 | E43: =IFERROR(SUMIFS(Base_Majoration!$J$2:$J$21,Base_Majoration!$A$2:$A$21,$A43,Base_Majoration!$B$2:$B$21,B$39),"") -> 11.78 | F43: =IFERROR(SUMIFS(Base_Majoration!$J$2:$J$21,Base_Majoration!$A$2:$A$21,$A43,Base_Majoration!$B$2:$B$21,B$39),"") -> 11.78
